Workbook

Sheet Médicos
A1: FECHA | B1: INVNUM | C1: COMPROBANTE | D1: FACTURA | E1: TIPO PAGO | F1: # DOC | G1: PACIENTE | H1: DNI | I1: MEDICO | J1: INSTITUCIÓN | K1: CARTERA | L1: HISTORIA | M1: TELEFONO | N1: RAZON SOCIAL | O1: PREFACTURA | P1: DESCRIPCION | Q1: CANTIDAD | R1: DESCRIP PLAN | S1: CONTRATANTE | T1: ASEGURADORA | U1: SEDEXX | V1: FACTURADOR | W1: FAC TOTAL | X1: CENTRO_COSTO | Y1: CONVENIO | Z1: SEDE | AA1: CELULAR | AB1: CUENTA BANCARIA
A2: 46174 | B2: 97734 | C2: BO | D2: 5483 | E2: CO | F2: BO-5483 | G2: MARIN DIAZ JORGE MARCIAL | H2: 06105706 | I2: ORNA ACOSTA JORGE AQUILES | J2: HOSPITAL LOAYZA | K2: CRISTINA | L2: 0069701 | M2: 990056060 | N2: MARIN DIAZ JORGE MARCIAL | O2: 85829 | P2: OCT DE MACULA | Q2: 1 | R2: PRECISA | S2: POR ASIGNAR | T2: INSTITUTO MEDICO QUIRURGICO AREQUIPA S.A | U2: L.CENTRO | V2: ACABRERA | W2: 186.44 | X2: LN. EXAMENES | Y2: CIAS. DE SEGURO | Z2: CENTRO | AA2: 999996347 | AB2: 052-7510523
A3: 46174 | B3: 97768 | C3: BO | D3: 11380 | E3: CO | F3: BO-11380 | G3: DAVILA URIBE JOSELUIS FRANKLIN | H3: 63710675 | I3: PEÑA CAMARGO CRISTOPHER OMAR | J3: HOSPITAL SERGIO BERNALES | K3: CRISTINA | L3: 0069713 | M3: 916691513 | N3: DAVILA URIBE JOSELUIS FRANKLIN | O3: 85858 | P3: OCT DE MACULA | Q3: 1 | R3: PRECISA | S3: POR ASIGNAR | T3: INSTITUTO MEDICO QUIRURGICO AREQUIPA S.A | U3: L.CENTRO | V3: LMAGAN | W3: 186.44 | X3: LN. EXAMENES | Y3: CIAS. DE SEGURO | Z3: CENTRO | AA3: 964328569 | AB3: 191-70241223029
A4: 46174 | B4: 97737 | C4: BO | D4: 5485 | E4: CO | F4: BO-5485 | G4: JIMENEZ BORCKARDT MARIA ELENA | H4: 09175695 | I4: TORRES LEAL ADOLFO LEON | J4: CLÍNICA SAN FELIPE LA MOLINA | K4: CRISTINA | L4: 0069704 | M4: 962711137 | N4: JIMENEZ BORCKARDT MARIA ELENA | O4: 85831 | P4: ECOGRAFIA OCULAR GENERAL SCAN A,B | Q4: 1 | R4: PRECISA | S4: POR ASIGNAR | T4: INSTITUTO MEDICO QUIRURGICO AREQUIPA S.A | U4: L.CENTRO | V4: ACABRERA | W4: 135.59 | X4: LN. EXAMENES | Y4: CIAS. DE SEGURO | Z4: CENTRO | AA4: 999421990
A5: 46174 | B5: 97761 | C5: BO | D5: 11378 | E5: CO | F5: BO-11378 | G5: SANDOVAL SANTAMARIA ANTERO | H5: 17562410 | I5: HUARANGA RUIZ CORNEJO JORGE ERNESTO | J5: HOSPITAL MONGRUT | K5: CRISTINA | L5: 0069712 | M5: 956259223 | N5: SANDOVAL SANTAMARIA ANTERO | O5: 85854 | P5: ECOGRAFIA OCULAR GENERAL SCAN A,B | Q5: 1 | R5: PRECISA | S5: POR ASIGNAR | T5: INSTITUTO MEDICO QUIRURGICO AREQUIPA S.A | U5: L.CENTRO | V5: LMAGAN | W5: 135.59 | X5: LN. EXAMENES | Y5: CIAS. DE SEGURO | Z5: CENTRO | AA5: 945319366 | AB5: 194-94066798065
A6: 46174 | B6: 97762 | C6: BO | D6: 3764 | E6: CO | F6: BO-3764 | G6: DIAZ DIAZ MARIA JUANA | H6: 48820433 | I6: AGRAMONTE ZEA EDILBERTO | J6: HOSPITAL DE LA SOLIDARIDAD SJL | K6: CRISTINA | L6: 0068509 | M6: 980843789 | N6: DIAZ DIAZ MARIA JUANA | O6: 85855 | P6: ECOGRAFIA OCULAR GENERAL SCAN A,B | Q6: 1 | R6: PRECISA LN | S6: POR ASIGNAR | T6: INSTITUTO MEDICO QUIRURGICO AREQUIPA S.A | U6: L.NORTE | V6: BGALLOSA | W6: 135.59 | X6: LN. EXAMENES | Y6: CIAS. DE SEGURO | Z6: NORTE | AA6: 987407712 | AB6: 0011-0190-0200333106
A7: 46174 | B7: 97751 | C7: BO | D7: 11374 | E7: CO | F7: BO-11374 | G7: HERRERA GRANDA VANNIA LUZ | H7: 77928579 | I7: PEÑA CAMARGO CRISTOPHER OMAR | J7: HOSPITAL SERGIO BERNALES | K7: CRISTINA | L7: 0067338 | M7: 953421025 | N7: HERRERA GRANDA VANNIA LUZ | O7: 85844 | P7: OCT DE NERVIO OPTICO Y CELULAS GANGLION | Q7: 1 | R7: PRECISA | S7: POR ASIGNAR | T7: INSTITUTO MEDICO QUIRURGICO AREQUIPA S.A | U7: L.CENTRO | V7: LMAGAN | W7: 186.44 | X7: LN. EXAMENES | Y7: CIAS. DE SEGURO | Z7: CENTRO | AA7: 964328569 | AB7: 191-70241223029
A8: 46175 | B8: 97877 | C8: BO | D8: 5505 | E8: CO | F8: BO-5505 | G8: REATEGUI VALLES REITER | H8: 01092510 | I8: MANSILLA JUAN JOSÉ | J8: CONSULTORIO PARTICULAR | K8: CRISTINA | L8: 0069757 | M8: 931872630 | N8: REATEGUI VALLES REITER | O8: 85945 | P8: USO DE EQUIPOS E INSUMO AVASTIN | Q8: 1 | R8: PRECISA | S8: POR ASIGNAR | T8: INSTITUTO MEDICO QUIRURGICO AREQUIPA S.A | U8: L.CENTRO | V8: ACABRERA | W8: 254.24 | X8: LN. PROCEDIMIENTO | Y8: CIAS. DE SEGURO | Z8: CENTRO
A9: 46176 | B9: 97907 | C9: BO | D9: 5506 | E9: CO | F9: BO-5506 | G9: MOTTA MARTINEZ JUSTINA OTILIA | H9: 08795262 | I9: RODRIGUEZ CECILIA | J9: POLICLÍNICO DIVINO NIÑO JESÚS | K9: CRISTINA | L9: 0054360 | M9: 901653281 | N9: MOTTA MARTINEZ JUSTINA OTILIA | O9: 85960 | P9: CAMPIMETRIA (CAMPO VISUAL) | Q9: 1 | R9: PRECISA | S9: POR ASIGNAR | T9: INSTITUTO MEDICO QUIRURGICO AREQUIPA S.A | U9: L.CENTRO | V9: ACABRERA | W9: 135.59 | X9: LN. EXAMENES | Y9: CIAS. DE SEGURO | Z9: CENTRO
A10: 46176 | B10: 97912 | C10: BO | D10: 11395 | E10: CO | F10: BO-11395 | G10: MEDINA SILVESTRE GERONIMO | H10: 06279020 | I10: GUTARRA PAUCAR JULIA KARINA | J10: CLÍNICA SAN CAMILO | K10: CRISTINA | L10: 0069754 | M10: 997332688 | N10: MEDINA SILVESTRE GERONIMO | O10: 85967 | P10: OCT DE MACULA | Q10: 1 | R10: PRECISA | S10: POR ASIGNAR | T10: INSTITUTO MEDICO QUIRURGICO AREQUIPA S.A | U10: L.CENTRO | V10: LMAGAN | W10: 186.44 | X10: LN. EXAMENES | Y10: CIAS. DE SEGURO | Z10: CENTRO | AA10: 982673362 | AB10: 0011-0353-0200308107
A11: 46176 | B11: 97912 | C11: BO | D11: 11395 | E11: CO | F11: BO-11395 | G11: MEDINA SILVESTRE GERONIMO | H11: 06279020 | I11: GUTARRA PAUCAR JULIA KARINA | J11: CLÍNICA SAN CAMILO | K11: CRISTINA | L11: 0069754 | M11: 997332688 | N11: MEDINA SILVESTRE GERONIMO | O11: 85967 | P11: OCT DE NERVIO OPTICO Y CELULAS GANGLION | Q11: 1 | R11: PRECISA | S11: POR ASIGNAR | T11: INSTITUTO MEDICO QUIRURGICO AREQUIPA S.A | U11: L.CENTRO | V11: LMAGAN | W11: 186.44 | X11: LN. EXAMENES | Y11: CIAS. DE SEGURO | Z11: CENTRO | AA11: 982673362 | AB11: 0011-0353-0200308107
A12: 46176 | B12: 97956 | C12: BO | D12: 11402 | E12: CO | F12: BO-11402 | G12: GARCIA DE SANCHEZ MATILDE | H12: 27062832 | I12: GUTARRA PAUCAR JULIA KARINA | J12: CLÍNICA SAN CAMILO | K12: CRISTINA | L12: 0069790 | M12: 917095913 | N12: GARCIA DE SANCHEZ MATILDE | O12: 86014 | P12: OCT DE MACULA | Q12: 1 | R12: PRECISA | S12: POR ASIGNAR | T12: INSTITUTO MEDICO QUIRURGICO AREQUIPA S.A | U12: L.CENTRO | V12: LMAGAN | W12: 186.44 | X12: LN. EXAMENES | Y12: CIAS. DE SEGURO | Z12: CENTRO | AA12: 982673362 | AB12: 0011-0353-0200308107
A13: 46176 | B13: 97956 | C13: BO | D13: 11402 | E13: CO | F13: BO-11402 | G13: GARCIA DE SANCHEZ MATILDE | H13: 27062832 | I13: GUTARRA PAUCAR JULIA KARINA | J13: CLÍNICA SAN CAMILO | K13: CRISTINA | L13: 0069790 | M13: 917095913 | N13: GARCIA DE SANCHEZ MATILDE | O13: 86014 | P13: OCT DE NERVIO OPTICO Y CELULAS GANGLION | Q13: 1 | R13: PRECISA | S13: POR ASIGNAR | T13: INSTITUTO MEDICO QUIRURGICO AREQUIPA S.A | U13: L.CENTRO | V13: LMAGAN | W13: 186.44 | X13: LN. EXAMENES | Y13: CIAS. DE SEGURO | Z13: CENTRO | AA13: 982673362 | AB13: 0011-0353-0200308107
A14: 46176 | B14: 97979 | C14: BO | D14: 11406 | E14: CO | F14: BO-11406 | G14: PEREZ SANCHEZ GIOVANNA MARIELA | H14: 25792949 | I14: BOBBIO PEREZ MILKO | J14: CONSULTORIO | K14: CRISTINA | L14: 0069797 | M14: 946068386 | N14: PEREZ SANCHEZ GIOVANNA MARIELA | O14: 86027 | P14: OCT DE MACULA | Q14: 1 | R14: PRECISA | S14: POR ASIGNAR | T14: INSTITUTO MEDICO QUIRURGICO AREQUIPA S.A | U14: L.CENTRO | V14: LMAGAN | W14: 186.44 | X14: LN. EXAMENES | Y14: CIAS. DE SEGURO | Z14: CENTRO | AA14: 981214114 | AB14: 191-98432106068
A15: 46176 | B15: 97979 | C15: BO | D15: 11406 | E15: CO | F15: BO-11406 | G15: PEREZ SANCHEZ GIOVANNA MARIELA | H15: 25792949 | I15: BOBBIO PEREZ MILKO | J15: CONSULTORIO | K15: CRISTINA | L15: 0069797 | M15: 946068386 | N15: PEREZ SANCHEZ GIOVANNA MARIELA | O15: 86027 | P15: PAQUIMETRIA | Q15: 1 | R15: PRECISA | S15: POR ASIGNAR | T15: INSTITUTO MEDICO QUIRURGICO AREQUIPA S.A | U15: L.CENTRO | V15: LMAGAN | W15: 152.54 | X15: LN. EXAMENES | Y15: CIAS. DE SEGURO | Z15: CENTRO | AA15: 981214114 | AB15: 191-98432106068
A16: 46177 | B16: 98036 | C16: BO | D16: 5516 | E16: CO | F16: BO-5516 | G16: PICO DE CRUZADO LUZ EMILIA | H16: 16550311 | I16: AGRAMONTE ZEA EDILBERTO | J16: HOSPITAL DE LA SOLIDARIDAD SJL | K16: CRISTINA | L16: 0069819 | M16: 985411444 | N16: PICO DE CRUZADO LUZ EMILIA | O16: 86087 | P16: OCT DE MACULA | Q16: 1 | R16: PRECISA | S16: POR ASIGNAR | T16: INSTITUTO MEDICO QUIRURGICO AREQUIPA S.A | U16: L.CENTRO | V16: ACABRERA | W16: 186.44 | X16: LN. EXAMENES | Y16: CIAS. DE SEGURO | Z16: CENTRO | AA16: 987407712 | AB16: 0011-0190-0200333106
A17: 46177 | B17: 98044 | C17: BO | D17: 11419 | E17: CO | F17: BO-11419 | G17: SACHA NAVARRO GERARDO JUNIOR | H17: 47180662 | I17: CACERES PINTO ALVARO DANIEL | J17: HOSPITAL INO | K17: CRISTINA | L17: 0069825 | M17: 958365826 | N17: SACHA NAVARRO GERARDO JUNIOR | O17: 86096 | P17: FOTOCLINICA EN MOSAICO | Q17: 1 | R17: PRECISA | S17: POR ASIGNAR | T17: INSTITUTO MEDICO QUIRURGICO AREQUIPA S.A | U17: L.CENTRO | V17: LMAGAN | W17: 169.49 | X17: LN. EXAMENES | Y17: CIAS. DE SEGURO | Z17: CENTRO | AA17: 966697811 | AB17: 0011-0184-0200649518
A18: 46177 | B18: 98044 | C18: BO | D18: 11419 | E18: CO | F18: BO-11419 | G18: SACHA NAVARRO GERARDO JUNIOR | H18: 47180662 | I18: CACERES PINTO ALVARO DANIEL | J18: HOSPITAL INO | K18: CRISTINA | L18: 0069825 | M18: 958365826 | N18: SACHA NAVARRO GERARDO JUNIOR | O18: 86096 | P18: OCT DE MACULA | Q18: 1 | R18: PRECISA | S18: POR ASIGNAR | T18: INSTITUTO MEDICO QUIRURGICO AREQUIPA S.A | U18: L.CENTRO | V18: LMAGAN | W18: 186.44 | X18: LN. EXAMENES | Y18: CIAS. DE SEGURO | Z18: CENTRO | AA18: 966697811 | AB18: 0011-0184-0200649518
A19: 46177 | B19: 98044 | C19: BO | D19: 11419 | E19: CO | F19: BO-11419 | G19: SACHA NAVARRO GERARDO JUNIOR | H19: 47180662 | I19: CACERES PINTO ALVARO DANIEL | J19: HOSPITAL INO | K19: CRISTINA | L19: 0069825 | M19: 958365826 | N19: SACHA NAVARRO GERARDO JUNIOR | O19: 86096 | P19: OCT DE NERVIO OPTICO Y CELULAS GANGLION | Q19: 1 | R19: PRECISA | S19: POR ASIGNAR | T19: INSTITUTO MEDICO QUIRURGICO AREQUIPA S.A | U19: L.CENTRO | V19: LMAGAN | W19: 186.44 | X19: LN. EXAMENES | Y19: CIAS. DE SEGURO | Z19: CENTRO | AA19: 966697811 | AB19: 0011-0184-0200649518
A20: 46177 | B20: 98041 | C20: FA | D20: 1025 | E20: CO | F20: FA-1025 | G20: NUÑEZ ALTIS ANTONIO SALOMON | H20: 09498424 | I20: VILLAR CURAHUA MARCELA ALEJANDRA | J20: GAMARRA SALUD | K20: CRISTINA | L20: 0069549 | M20: 928076253 | N20: GAMARRA HEALTHCARE CENTER S.A.C. | O20: 86093 | P20: BIOMETRIA IOL MASTER 700 | Q20: 1 | R20: PRECISA | S20: POR ASIGNAR | T20: INSTITUTO MEDICO QUIRURGICO AREQUIPA S.A | U20: L.CENTRO | V20: LMAGAN | W20: 152.54 | X20: LN. EXAMENES | Y20: CIAS. DE SEGURO | Z20: CENTRO | AA20: 950133748 | AB20: 191-9953047026
A21: 46177 | B21: 98041 | C21: FA | D21: 1025 | E21: CO | F21: FA-1025 | G21: NUÑEZ ALTIS ANTONIO SALOMON | H21: 09498424 | I21: VILLAR CURAHUA MARCELA ALEJANDRA | J21: GAMARRA SALUD | K21: CRISTINA | L21: 0069549 | M21: 928076253 | N21: GAMARRA HEALTHCARE CENTER S.A.C. | O21: 86093 | P21: MICROSCOPIA ESPECULAR | Q21: 1 | R21: PRECISA | S21: POR ASIGNAR | T21: INSTITUTO MEDICO QUIRURGICO AREQUIPA S.A | U21: L.CENTRO | V21: LMAGAN | W21: 135.59 | X21: LN. EXAMENES | Y21: CIAS. DE SEGURO | Z21: CENTRO | AA21: 950133748 | AB21: 191-9953047026
... A31: 46178 | B31: 2353 | C31: BO | D31: 5527 | E31: CR | F31: BO-5527 | G31: BRAVO QUISPE VDA DE ANDIA ANGELICA RITA | H31: 07412423 | I31: FERNANDEZ GUTIERREZ OLGA PATRICIA | J31: CONSULTORIO PARTICULAR | K31: CR | L31: 0069850 | M31: 979750580 | N31: BRAVO QUISPE VDA DE ANDIA ANGELICA RITA | O31: 86154 | P31: USO DE EQUIPOS E INSUMO IRIDOTOMIA | Q31: 2 | R31: PRECISA | S31: POR ASIGNAR | T31: INSTITUTO MEDICO QUIRURGICO AREQUIPA S.A | U31: L.CENTRO | V31: ACABRERA | W31: 203.39 | X31: LN. PROCEDIMIENTO | Y31: CIAS. DE SEGURO | Z31: CENTRO | AA31: 982536223 | AB31: 107-3174605363
A32: 46178 | B32: 98108 | C32: FA | D32: 526 | E32: CO | F32: FA-526 | G32: ABAD OVALLE ARLINE MERCEDES | H32: 25532349 | K32: CRISTINA | L32: 0069694 | M32: 999999452 | N32: VEFER OFTALMOLOGOS S.A.C. | O32: 86152 | P32: USO DE EQUIPOS E INSUMO IRIDOTOMIA | Q32: 2 | R32: PRECISA | S32: POR ASIGNAR | T32: INSTITUTO MEDICO QUIRURGICO AREQUIPA S.A | U32: L.CENTRO | V32: ACABRERA | W32: 203.39 | X32: LN. PROCEDIMIENTO | Y32: CIAS. DE SEGURO | Z32: CENTRO
A33: 46179 | B33: 98152 | C33: BO | D33: 4244 | E33: CO | F33: BO-4244 | G33: OLIVO CASTRO JULIA GLADYS | H33: 15292242 | I33: RUIZ ROJAS PAUBLO ENRIQUE | J33: CONSULTORIO CUBANO COMAS | K33: CRISTINA | L33: 0069884 | M33: 952190646 | N33: OLIVO CASTRO JULIA GLADYS | O33: 86190 | P33: OCT DE MACULA | Q33: 1 | R33: PRECISA LN | S33: POR ASIGNAR | T33: INSTITUTO MEDICO QUIRURGICO AREQUIPA S.A | U33: L.NORTE | V33: AALARCON | W33: 186.44 | X33: LN. EXAMENES | Y33: CIAS. DE SEGURO | Z33: NORTE | AA33: 992903716 | AB33: 191-91415089071
A34: 46179 | B34: 98151 | C34: BO | D34: 11423 | E34: CO | F34: BO-11423 | G34: PACACHA FLORES BLANCA VALESKA | H34: 91733805 | I34: CRISPIN MORALES NANCY JENNY | J34: HOSPITAL ALMENARA | K34: CRISTINA | L34: 0069883 | M34: 970593962 | N34: PACACHA FLORES BLANCA VALESKA | O34: 86188 | P34: TOPOGRAFIA CORNEAL | Q34: 1 | R34: PRECISA | S34: POR ASIGNAR | T34: INSTITUTO MEDICO QUIRURGICO AREQUIPA S.A | U34: L.CENTRO | V34: LMAGAN | W34: 152.54 | X34: LN. EXAMENES | Y34: CIAS. DE SEGURO | Z34: CENTRO | AA34: 978789268 | AB34: 193-90416675072
A35: 46179 | B35: 98176 | C35: BO | D35: 11428 | E35: CO | F35: BO-11428 | G35: REYES SANCHEZ OLGA EULALIA | H35: 09330262 | I35: LLERENA MORALES OSCAR ADOLFO | J35: SANNA SAN MIGUEL | K35: CRISTINA | L35: 0069894 | M35: 947513770 | N35: REYES SANCHEZ OLGA EULALIA | O35: 86218 | P35: CAMPIMETRIA (CAMPO VISUAL) | Q35: 1 | R35: PRECISA | S35: POR ASIGNAR | T35: INSTITUTO MEDICO QUIRURGICO AREQUIPA S.A | U35: L.CENTRO | V35: LMAGAN | W35: 135.59 | X35: LN. EXAMENES | Y35: CIAS. DE SEGURO | Z35: CENTRO | AA35: 987552890 | AB35: 098-7304409
A36: 46179 | B36: 98176 | C36: BO | D36: 11428 | E36: CO | F36: BO-11428 | G36: REYES SANCHEZ OLGA EULALIA | H36: 09330262 | I36: LLERENA MORALES OSCAR ADOLFO | J36: SANNA SAN MIGUEL | K36: CRISTINA | L36: 0069894 | M36: 947513770 | N36: REYES SANCHEZ OLGA EULALIA | O36: 86218 | P36: PAQUIMETRIA | Q36: 1 | R36: PRECISA | S36: POR ASIGNAR | T36: INSTITUTO MEDICO QUIRURGICO AREQUIPA S.A | U36: L.CENTRO | V36: LMAGAN | W36: 152.54 | X36: LN. EXAMENES | Y36: CIAS. DE SEGURO | Z36: CENTRO | AA36: 987552890 | AB36: 098-7304409
A37: 46179 | B37: 98176 | C37: BO | D37: 11428 | E37: CO | F37: BO-11428 | G37: REYES SANCHEZ OLGA EULALIA | H37: 09330262 | I37: LLERENA MORALES OSCAR ADOLFO | J37: SANNA SAN MIGUEL | K37: CRISTINA | L37: 0069894 | M37: 947513770 | N37: REYES SANCHEZ OLGA EULALIA | O37: 86218 | P37: OCT DE NERVIO OPTICO Y CELULAS GANGLION | Q37: 1 | R37: PRECISA | S37: POR ASIGNAR | T37: INSTITUTO MEDICO QUIRURGICO AREQUIPA S.A | U37: L.CENTRO | V37: LMAGAN | W37: 186.44 | X37: LN. EXAMENES | Y37: CIAS. DE SEGURO | Z37: CENTRO | AA37: 987552890 | AB37: 098-7304409
A38: 46179 | B38: 98167 | C38: BO | D38: 4250 | E38: CO | F38: BO-4250 | G38: RONCAL ROMERO FANNYNG EDITH | H38: 44905743 | I38: ROJAS AQUINO EVELING KARINA | J38: POLICLÍNICO ESPÍRITU SANTO | K38: CRISTINA | L38: 0069844 | M38: 984441413 | N38: RONCAL ROMERO FANNYNG EDITH | O38: 86210 | P38: OCT DE NERVIO OPTICO Y CELULAS GANGLION | Q38: 1 | R38: PRECISA LN | S38: POR ASIGNAR | T38: INSTITUTO MEDICO QUIRURGICO AREQUIPA S.A | U38: L.NORTE | V38: AALARCON | W38: 186.44 | X38: LN. EXAMENES | Y38: CIAS. DE SEGURO | Z38: NORTE | AA38: 955356636 | AB38: 009-3226956615
A39: 46182 | B39: 98452 | C39: FA | D39: 532 | E39: CO | F39: FA-532 | G39: BENITES RAMOS ANTENOR HERMAN | H39: 07187063 | I39: VILLAR CURAHUA MARCELA ALEJANDRA | J39: GAMARRA SALUD | K39: CRISTINA | L39: 0069415 | M39: 943410784 | N39: GAMARRA HEALTHCARE CENTER S.A.C. | O39: 86345 | P39: CIRUGIA DE DIA | Q39: 1 | R39: PRECISA | S39: POR ASIGNAR | T39: INSTITUTO MEDICO QUIRURGICO AREQUIPA S.A | U39: L.CENTRO | V39: ACABRERA | W39: 0 | X39: LN. CIRUGIA | Y39: CIAS. DE SEGURO | Z39: CENTRO | AA39: 950133748 | AB39: 191-9953047026
A40: 46182 | B40: 98452 | C40: FA | D40: 532 | E40: CO | F40: FA-532 | G40: BENITES RAMOS ANTENOR HERMAN | H40: 07187063 | I40: VILLAR CURAHUA MARCELA ALEJANDRA | J40: GAMARRA SALUD | K40: CRISTINA | L40: 0069415 | M40: 943410784 | N40: GAMARRA HEALTHCARE CENTER S.A.C. | O40: 86345 | P40: FACOEMULSIFICACION PRIMIUM | Q40: 1 | R40: PRECISA | S40: POR ASIGNAR | T40: INSTITUTO MEDICO QUIRURGICO AREQUIPA S.A | U40: L.CENTRO | V40: ACABRERA | W40: 1050.85 | X40: LN. CIRUGIA | Y40: CIAS. DE SEGURO | Z40: CENTRO | AA40: 950133748 | AB40: 191-9953047026
A41: 46182 | B41: 98463 | C41: FA | D41: 533 | E41: CO | F41: FA-533 | G41: MAMANI SONCCO JUAN GREGORIO | H41: 07314057 | I41: VILLAR CURAHUA MARCELA ALEJANDRA | J41: GAMARRA SALUD | K41: CRISTINA | L41: 0069158 | M41: 987411587 | N41: GAMARRA HEALTHCARE CENTER S.A.C. | O41: 86342 | P41: CIRUGIA DE DIA | Q41: 1 | R41: PRECISA | S41: POR ASIGNAR | T41: INSTITUTO MEDICO QUIRURGICO AREQUIPA S.A | U41: L.CENTRO | V41: ACABRERA | W41: 0 | X41: LN. CIRUGIA | Y41: CIAS. DE SEGURO | Z41: CENTRO | AA41: 950133748 | AB41: 191-9953047026
A42: 46182 | B42: 98463 | C42: FA | D42: 533 | E42: CO | F42: FA-533 | G42: MAMANI SONCCO JUAN GREGORIO | H42: 07314057 | I42: VILLAR CURAHUA MARCELA ALEJANDRA | J42: GAMARRA SALUD | K42: CRISTINA | L42: 0069158 | M42: 987411587 | N42: GAMARRA HEALTHCARE CENTER S.A.C. | O42: 86342 | P42: FACOEMULSIFICACION PRIMIUM | Q42: 1 | R42: PRECISA | S42: POR ASIGNAR | T42: INSTITUTO MEDICO QUIRURGICO AREQUIPA S.A | U42: L.CENTRO | V42: ACABRERA | W42: 1050.85 | X42: LN. CIRUGIA | Y42: CIAS. DE SEGURO | Z42: CENTRO | AA42: 950133748 | AB42: 191-9953047026
A43: 46182 | B43: 98440 | C43: FA | D43: 1028 | E43: CO | F43: FA-1028 | G43: MATEO EYZAGUIRRE MARCO IVART | H43: 74312316 | I43: ACOSTA VIERA ALVARO | J43: CONSULTORIO PARTICULAR | K43: CRISTINA | L43: 0069588 | M43: 921508096 | N43: CENTRO CONTRA LA CEGUERA E.I.R.L. | O43: 86415 | P43: USO DE EQUIPOS E INSUMO BLEFAROPLASTIA | Q43: 1 | R43: PRECISA | S43: POR ASIGNAR | T43: INSTITUTO MEDICO QUIRURGICO AREQUIPA S.A | U43: L.CENTRO | V43: LMAGAN | W43: 169.49 | X43: LN. PROCEDIMIENTO | Y43: CIAS. DE SEGURO | Z43: CENTRO | AA43: 969791876 | AB43: 0011-0814-0256063048
A44: 46182 | B44: 98393 | C44: BO | D44: 5552 | E44: CO | F44: BO-5552 | G44: LAZARO CACHA JUAN CRISOSTOMO | H44: 31633639 | I44: FIERRO LEANDRO | J44: POLICLÍNICO DIVINO NIÑO JESÚS | K44: CRISTINA | L44: 0069870 | M44: 928408508 | N44: LAZARO CACHA JUAN CRISOSTOMO | O44: 86371 | P44: PQ BIOMETRIA MICROSCOPIA | Q44: 1 | R44: PRECISA | S44: POR ASIGNAR | T44: INSTITUTO MEDICO QUIRURGICO AREQUIPA S.A | U44: L.CENTRO | V44: ACABRERA | W44: 84.75 | X44: LN. EXAMENES | Y44: CIAS. DE SEGURO | Z44: CENTRO
A45: 46182 | B45: 98395 | C45: BO | D45: 11467 | E45: CO | F45: BO-11467 | G45: MENDOZA REYES BRIGIDA | H45: 08831402 | I45: FIERRO LEANDRO | J45: POLICLÍNICO DIVINO NIÑO JESÚS | K45: CRISTINA | L45: 0069872 | M45: 941194643 | N45: MENDOZA REYES BRIGIDA | O45: 86373 | P45: PQ BIOMETRIA MICROSCOPIA | Q45: 1 | R45: PRECISA | S45: POR ASIGNAR | T45: INSTITUTO MEDICO QUIRURGICO AREQUIPA S.A | U45: L.CENTRO | V45: LMAGAN | W45: 84.75 | X45: LN. EXAMENES | Y45: CIAS. DE SEGURO | Z45: CENTRO
A46: 46182 | B46: 98399 | C46: BO | D46: 5555 | E46: CO | F46: BO-5555 | G46: TINOCO OBREGON LUIS ALBERTO | H46: 15859654 | I46: FIERRO LEANDRO | J46: POLICLÍNICO DIVINO NIÑO JESÚS | K46: CRISTINA | L46: 0069871 | M46: 997639449 | N46: TINOCO OBREGON LUIS ALBERTO | O46: 86378 | P46: PQ BIOMETRIA MICROSCOPIA | Q46: 1 | R46: PRECISA | S46: POR ASIGNAR | T46: INSTITUTO MEDICO QUIRURGICO AREQUIPA S.A | U46: L.CENTRO | V46: ACABRERA | W46: 84.75 | X46: LN. EXAMENES | Y46: CIAS. DE SEGURO | Z46: CENTRO
A47: 46182 | B47: 98449 | C47: FA | D47: 530 | E47: CO | F47: FA-530 | G47: LAZARO CACHA JUAN CRISOSTOMO | H47: 31633639 | I47: FIERRO LEANDRO | J47: POLICLÍNICO DIVINO NIÑO JESÚS | K47: CRISTINA | L47: 0069870 | M47: 928408508 | N47: GRUPO MEDICO INTEGRAL SOCIEDAD ANONIMA CERRADA | O47: 86384 | P47: CIRUGIA DE DIA | Q47: 1 | R47: PRECISA | S47: POR ASIGNAR | T47: INSTITUTO MEDICO QUIRURGICO AREQUIPA S.A | U47: L.CENTRO | V47: ACABRERA | W47: 0 | X47: LN. CIRUGIA | Y47: CIAS. DE SEGURO | Z47: CENTRO
A48: 46182 | B48: 98449 | C48: FA | D48: 530 | E48: CO | F48: FA-530 | G48: LAZARO CACHA JUAN CRISOSTOMO | H48: 31633639 | I48: FIERRO LEANDRO | J48: POLICLÍNICO DIVINO NIÑO JESÚS | K48: CRISTINA | L48: 0069870 | M48: 928408508 | N48: GRUPO MEDICO INTEGRAL SOCIEDAD ANONIMA CERRADA | O48: 86384 | P48: FACOEMULSIFICACION PRIMIUM | Q48: 1 | R48: PRECISA | S48: POR ASIGNAR | T48: INSTITUTO MEDICO QUIRURGICO AREQUIPA S.A | U48: L.CENTRO | V48: ACABRERA | W48: 1525.42 | X48: LN. CIRUGIA | Y48: CIAS. DE SEGURO | Z48: CENTRO
A49: 46182 | B49: 98450 | C49: FA | D49: 531 | E49: CO | F49: FA-531 | G49: TINOCO OBREGON LUIS ALBERTO | H49: 15859654 | I49: FIERRO LEANDRO | J49: POLICLÍNICO DIVINO NIÑO JESÚS | K49: CRISTINA | L49: 0069871 | M49: 997639449 | N49: GRUPO MEDICO INTEGRAL SOCIEDAD ANONIMA CERRADA | O49: 86385 | P49: CIRUGIA DE DIA | Q49: 1 | R49: PRECISA | S49: POR ASIGNAR | T49: INSTITUTO MEDICO QUIRURGICO AREQUIPA S.A | U49: L.CENTRO | V49: ACABRERA | W49: 0 | X49: LN. CIRUGIA | Y49: CIAS. DE SEGURO | Z49: CENTRO
...

Sheet Cuentas
A1: Médico | B1: Celular | C1: Banco | D1: # Cuenta | E1: # CCI | F1: Institución | G1: Columna1
A2: CASTILLO JAVE NANDY | B2: 900734202 | C2: BANCO DE LA NACIÓN | D2: 04-531049328 | E2: 018-53100453104932848 | F2: HOSPITAL LOAYZA
A3: LINO LARREA CARLOS ENRIQUE | B3: 930793497 | C3: BANCO DE LA NACIÓN | D3: 04-261072713 | E3: 018-26100426107271385 | F3: HOSPITAL INO
A4: ZEBALLOS AYQUIPA MISHELLY JOHANA | B4: 949717538 | C4: BANCO DE LA NACIÓN | D4: 04-021092202 | E4: 018-00000402109220203 | F4: HOSPITAL DE POLICIA
A5: TRINIDAD MOLINA ZOSIMO | B5: 986294682 | C5: BANCO DE LA NACIÓN | D5: 04-042865309 | E5: 018-00000404286530907 | F5: VES
A6: ENTENZA NALIA | B6: 915394967 | C6: BBVA | D6: 0011-0814-0245234827 | E6: 011-814-000245234827-15 | F6: UNIDERMA JESUS MARÍA
A7: ESPINOZA LAVALLE CESAR FRANKZ | B7: 937242809 | C7: BBVA | D7: 0011-0057-0229787021 | E7: 011-057-000229787021-70 | F7: CLINICA DIVINO NIÑO JESÚS
A8: BARRANTES RAMIREZ ELENA JESUS AMERICA | B8: 940621858 | C8: BBVA | D8: 0011-0616-0200286900 | E8: 011-616-000200286900-02 | F8: OPELUCE LINCE
A9: HUAMAN MENDEZ NATHALY VANESSA | B9: 945751945 | C9: BBVA | D9: 0011-0186-0200772531 | F9: HOSPITAL DE POLICIA
A10: CASAVERDE VILLACORTA CARLOS ALBERTO | B10: 945930825 | C10: BBVA | D10: 0011-0486-0200014689 | E10: 011-486-000200014689-80 | F10: HOSPITAL GRAU
A11: PEREZ PRADO WILSON | B11: 947591368 | C11: BBVA | D11: 0011-0814-0238585177 | E11: 011-814-000238585177-15 | F11: HOSPITAL SERGIO BERNALES
A12: GAMERO FERNANDEZ EBERTH LELYS | B12: 948878123 | C12: BBVA | D12: 0011-0057-0209443814 | E12: 011-057-000209443814-76 | F12: CONSULTORIO PARTICULAR
A13: NUÑEZ DEL PRADO CUADROS MARIELA DIANA | B13: 959068627 | C13: BBVA | D13: 0011-0180-0200473345 | E13: 011-180-000200473345-73 | F13: HOSPITAL LOAYZA
A14: RIVERA FERNANDEZ JORGE GUSTAVO | B14: 959103507 | C14: BBVA | D14: 0011-0148-0200516341 | E14: 011-148-000200516341-41 | F14: CLINICA VER
A15: MONTOYA DELGADO MANUEL JESUS | B15: 959529890 | C15: BBVA | D15: 0011-0115-0100070311 | E15: 011-115-000100070311-34 | F15: CONSULTORIO
A16: CACERES PINTO ALVARO DANIEL | B16: 966697811 | C16: BBVA | D16: 0011-0184-0200649518 | E16: 011-184-000200649518-94 | F16: HOSPITAL INO
A17: GARRO ROSAS LUCIA | B17: 976498726 | C17: BBVA | D17: 0011-0148-0200614041 | E17: 011-148-000200614041-48 | F17: HOSPITAL SABOGAL
A18: FONTENLA SERNA DAVID IVAN | B18: 976922608 | C18: BBVA | D18: 0011-0117-0200577155 | E18: 011-117-000200577155-91 | F18: HOSPITAL NAVAL
A19: ALCOCER DE LA CRUZ REGINA ROCIO | B19: 981953525 | C19: BBVA | D19: 0011-0190-0200562504 | E19: 011-190-000200562504-67 | F19: OPELUCE LINCE
A20: GUTARRA PAUCAR JULIA KARINA | B20: 982673362 | C20: BBVA | D20: 0011-0353-0200308107 | E20: 0113-5300-0200308107-08 | F20: CLÍNICA SAN CAMILO
A21: ZUÑIGA SANCHEZ MARIA DEL PILAR | B21: 983338097 | C21: BBVA | D21: 0011-0057-0233799581 | E21: 011-057-000233799581-71 | F21: HOSPITAL ALMENARA
... A42: CONTRERAS SILVA ÁNGEL ALFREDO | B42: 997171889 | C42: BBVA | D42: 0011-0118-0200430370 | E42: 011-118-000200430370-73 | F42: CONSULTORIO PARTICULAR
A43: MEDRANO GUILLERMO LISSET | B43: 989704320 | C43: BBVA | D43: 0011-0189-0200431226 | F43: HOSPITAL DE LA SOLIDARIDAD
A44: LOPEZ MARTINEZ ALEXANDRA | B44: 929966474 | C44: BBVA | D44: 0011-0153-0200750511 | E44: 011-153-000200750511-44 | F44: HOSPITAL DE POLICIA
A45: RISCO CHANG ROXANA | B45: 961025690 | C45: BBVA | D45: 0011-0122-0200631866 | E45: 011-122-000200631866-97 | F45: CLINICA SAN GABRIEL
A46: SAAVEDRA ESPINOZA DARIELA MARIEL | B46: 991056603 | C46: BBVA | D46: 0011-0320-0200072928 | E46: 011-320-000200072928-91 | F46: HOSPITAL SABOGAL
A47: SANDOVAL ERQUINEO JHOVANA LICED | B47: 939369228 | C47: BBVA | D47: 0011-0057-0219092475 | E47: 011-057-000219092475-79 | F47: HOSPITAL SERGIO BERNALES
A48: YOVERA LEYVA ELSA MARIANELA | B48: 982192071 | C48: BBVA | D48: 0011-0320-0200277139 | E48: 011-320-000200277139-98 | F48: HOSPITAL 2 DE MAYO
A49: ÑAUPARI MEZA BRENNER ALBERTO | B49: 940248463 | C49: BBVA | D49: 0011-0712-0200343264 | E49: 011-712-000200343264-74 | F49: HOSPITAL ALMENARA
A50: ALVARO TAMBRA WENDY CAROLA | B50: 972627309 | C50: BBVA | D50: 0011-0320-0200061187 | E50: 011-320-000200061187-97 | F50: POLICLÍNICO PABLO BERMUDEZ
A51: PUICAN NAVARRO GUIDO ALFREDO | B51: 999088459 | C51: BBVA | D51: 0011-0286-0200053326 | E51: 011-286-000200053326-21 | F51: CONSULTORIO PARTICULAR
A52: JANAMPA CAMPOS WILSON ALEXANDER | B52: 926323940 | C52: BCP | D52: 315-99346437032 | E52: 00231519934643703204 | F52: HOSPITAL SAN JOSE
A53: QUIROZ MONTOYA CLAUDIA MICHAEL | B53: 931781027 | C53: BCP | D53: 191-14161745092 | E53: 00219111416174509250 | F53: HOSPITAL HIPOLITO UNANUE
A54: SANTE MORALES JOEL EDMUNDO | B54: 941044046 | C54: BCP | D54: 430-32526176035 | E54: 00243013252617603579 | F54: CONSULTORIO PARTICULAR
A55: BARREDA FUENTES ANDRES DANIEL | B55: 941411075 | C55: BCP | D55: 193-36174976078 | E55: 00219313617497607000 | F55: HOSPITAL DE POLICIA
A56: GALINDO SIHUIN YOSELL RAFAEL | B56: 942457955 | C56: BCP | D56: 192-99257733034 | E56: 00219219925773303430
A57: CARDENAS ROLANDO | B57: 943196346 | C57: BCP | D57: 193-04298551069 | E57: 00219310429855106913 | F57: HOSPITAL INO
A58: HOYOS SAENZ ANGELA | B58: 945127415 | C58: BCP | D58: 245-99508929094 | E58: 00224519950892909494 | F58: HOSPITAL LOAYZA
A59: CARDENAS ORTEGA MARISA | B59: 947054605 | C59: BCP | D59: 193-34139202041 | E59: 00219313413920204000 | F59: CONSULTORIO
A60: HERNANDEZ PEÑA ARTURO GABRIEL | B60: 949900695 | C60: BCP | D60: 191-15421658031 | E60: 00219111542165803150 | F60: HOSPITAL DE POLICIA
...

Sheet Bonos2
A1: Servicios | B1: Precio Bono
A2: ANGIOGRAFIA CON FLUORESCEINA | B2: 100
A3: BIOMETRIA IOL MASTER 700 | B3: 30
A4: CAMPIMETRIA (CAMPO VISUAL) | B4: 30
A5: ECOGRAFIA OCULAR GENERAL SCAN A,B | B5: 30
A6: MICROSCOPIA ESPECULAR | B6: 30
A7: OCT ANGIOGRAFIA NERVIO OPTICO | B7: 50
A8: OCT DE MACULA | B8: 50
A9: OCT DE NERVIO OPTICO Y CELULAS GANGLION | B9: 50
A10: OCT DE SEGMENTO ANTERIOR (ANGULOS) | B10: 50
A11: PAQUIMETRIA | B11: 30
A12: TOPOGRAFIA CORNEAL | B12: 30
A13: FOTOCLINICA EN MOSAICO | B13: 50
... A18: ECOBIOMETRIA OCULAR UNILATERAL O BILATER | B18: 30

Sheet Base_Precisa
A1: FECHA | B1: MES | C1: INVNUM | D1: COMPROBANTE | E1: FACTURA | F1: TIPO PAGO | G1: # DOC | H1: PACIENTE | I1: DNI | J1: MEDICO | K1: INSTITUCIÓN | L1: CARTERA | M1: HISTORIA | N1: TELEFONO | O1: RAZON SOCIAL | P1: PREFACTURA | Q1: DESCRIPCION | R1: CANTIDAD | S1: DESCRIP PLAN | T1: CONTRATANTE | U1: ASEGURADORA | V1: SEDEXX | W1: FACTURADOR | X1: FAC TOTAL | Y1: CENTRO_COSTO | Z1: CONVENIO | AA1: SEDE | AB1: CELULAR | AC1: CUENTA BANCARIA | AD1: Bono
A2: 46174 | B2: Junio | C2: 97734 | D2: BO | E2: 5483 | F2: CO | G2: BO-5483 | H2: MARIN DIAZ JORGE MARCIAL | I2: 06105706 | J2: ORNA ACOSTA JORGE AQUILES | K2: HOSPITAL LOAYZA | L2: CRISTINA | M2: 0069701 | N2: 990056060 | O2: MARIN DIAZ JORGE MARCIAL | P2: 85829 | Q2: OCT DE MACULA | R2: 1 | S2: PRECISA | T2: POR ASIGNAR | U2: INSTITUTO MEDICO QUIRURGICO AREQUIPA S.A | V2: L.CENTRO | W2: ACABRERA | X2: 186.44 | Y2: LN. EXAMENES | Z2: CIAS. DE SEGURO | AA2: CENTRO | AB2: 999996347 | AC2: 052-7510523 | AD2: 50
A3: 46174 | B3: Junio | C3: 97768 | D3: BO | E3: 11380 | F3: CO | G3: BO-11380 | H3: DAVILA URIBE JOSELUIS FRANKLIN | I3: 63710675 | J3: PEÑA CAMARGO CRISTOPHER OMAR | K3: HOSPITAL SERGIO BERNALES | L3: CRISTINA | M3: 0069713 | N3: 916691513 | O3: DAVILA URIBE JOSELUIS FRANKLIN | P3: 85858 | Q3: OCT DE MACULA | R3: 1 | S3: PRECISA | T3: POR ASIGNAR | U3: INSTITUTO MEDICO QUIRURGICO AREQUIPA S.A | V3: L.CENTRO | W3: LMAGAN | X3: 186.44 | Y3: LN. EXAMENES | Z3: CIAS. DE SEGURO | AA3: CENTRO | AB3: 964328569 | AC3: 191-70241223029 | AD3: 50
A4: 46174 | B4: Junio | C4: 97737 | D4: BO | E4: 5485 | F4: CO | G4: BO-5485 | H4: JIMENEZ BORCKARDT MARIA ELENA | I4: 09175695 | J4: TORRES LEAL ADOLFO LEON | K4: CLÍNICA SAN FELIPE LA MOLINA | L4: CRISTINA | M4: 0069704 | N4: 962711137 | O4: JIMENEZ BORCKARDT MARIA ELENA | P4: 85831 | Q4: ECOGRAFIA OCULAR GENERAL SCAN A,B | R4: 1 | S4: PRECISA | T4: POR ASIGNAR | U4: INSTITUTO MEDICO QUIRURGICO AREQUIPA S.A | V4: L.CENTRO | W4: ACABRERA | X4: 135.59 | Y4: LN. EXAMENES | Z4: CIAS. DE SEGURO | AA4: CENTRO | AB4: 999421990 | AD4: 30
A5: 46174 | B5: Junio | C5: 97761 | D5: BO | E5: 11378 | F5: CO | G5: BO-11378 | H5: SANDOVAL SANTAMARIA ANTERO | I5: 17562410 | J5: HUARANGA RUIZ CORNEJO JORGE ERNESTO | K5: HOSPITAL MONGRUT | L5: CRISTINA | M5: 0069712 | N5: 956259223 | O5: SANDOVAL SANTAMARIA ANTERO | P5: 85854 | Q5: ECOGRAFIA OCULAR GENERAL SCAN A,B | R5: 1 | S5: PRECISA | T5: POR ASIGNAR | U5: INSTITUTO MEDICO QUIRURGICO AREQUIPA S.A | V5: L.CENTRO | W5: LMAGAN | X5: 135.59 | Y5: LN. EXAMENES | Z5: CIAS. DE SEGURO | AA5: CENTRO | AB5: 945319366 | AC5: 194-94066798065 | AD5: 30
A6: 46174 | B6: Junio | C6: 97762 | D6: BO | E6: 3764 | F6: CO | G6: BO-3764 | H6: DIAZ DIAZ MARIA JUANA | I6: 48820433 | J6: AGRAMONTE ZEA EDILBERTO | K6: HOSPITAL DE LA SOLIDARIDAD SJL | L6: CRISTINA | M6: 0068509 | N6: 980843789 | O6: DIAZ DIAZ MARIA JUANA | P6: 85855 | Q6: ECOGRAFIA OCULAR GENERAL SCAN A,B | R6: 1 | S6: PRECISA LN | T6: POR ASIGNAR | U6: INSTITUTO MEDICO QUIRURGICO AREQUIPA S.A | V6: L.NORTE | W6: BGALLOSA | X6: 135.59 | Y6: LN. EXAMENES | Z6: CIAS. DE SEGURO | AA6: NORTE | AB6: 987407712 | AC6: 0011-0190-0200333106 | AD6: 30
A7: 46174 | B7: Junio | C7: 97751 | D7: BO | E7: 11374 | F7: CO | G7: BO-11374 | H7: HERRERA GRANDA VANNIA LUZ | I7: 77928579 | J7: PEÑA CAMARGO CRISTOPHER OMAR | K7: HOSPITAL SERGIO BERNALES | L7: CRISTINA | M7: 0067338 | N7: 953421025 | O7: HERRERA GRANDA VANNIA LUZ | P7: 85844 | Q7: OCT DE NERVIO OPTICO Y CELULAS GANGLION | R7: 1 | S7: PRECISA | T7: POR ASIGNAR | U7: INSTITUTO MEDICO QUIRURGICO AREQUIPA S.A | V7: L.CENTRO | W7: LMAGAN | X7: 186.44 | Y7: LN. EXAMENES | Z7: CIAS. DE SEGURO | AA7: CENTRO | AB7: 964328569 | AC7: 191-70241223029 | AD7: 50
A8: 46175 | B8: Junio | C8: 97877 | D8: BO | E8: 5505 | F8: CO | G8: BO-5505 | H8: REATEGUI VALLES REITER | I8: 01092510 | J8: MANSILLA JUAN JOSÉ | K8: CONSULTORIO PARTICULAR | L8: CRISTINA | M8: 0069757 | N8: 931872630 | O8: REATEGUI VALLES REITER | P8: 85945 | Q8: USO DE EQUIPOS E INSUMO AVASTIN | R8: 1 | S8: PRECISA | T8: POR ASIGNAR | U8: INSTITUTO MEDICO QUIRURGICO AREQUIPA S.A | V8: L.CENTRO | W8: ACABRERA | X8: 254.24 | Y8: LN. PROCEDIMIENTO | Z8: CIAS. DE SEGURO | AA8: CENTRO
A9: 46176 | B9: Junio | C9: 97907 | D9: BO | E9: 5506 | F9: CO | G9: BO-5506 | H9: MOTTA MARTINEZ JUSTINA OTILIA | I9: 08795262 | J9: RODRIGUEZ CECILIA | K9: POLICLÍNICO DIVINO NIÑO JESÚS | L9: CRISTINA | M9: 0054360 | N9: 901653281 | O9: MOTTA MARTINEZ JUSTINA OTILIA | P9: 85960 | Q9: CAMPIMETRIA (CAMPO VISUAL) | R9: 1 | S9: PRECISA | T9: POR ASIGNAR | U9: INSTITUTO MEDICO QUIRURGICO AREQUIPA S.A | V9: L.CENTRO | W9: ACABRERA | X9: 135.59 | Y9: LN. EXAMENES | Z9: CIAS. DE SEGURO | AA9: CENTRO | AD9: 30
A10: 46176 | B10: Junio | C10: 97912 | D10: BO | E10: 11395 | F10: CO | G10: BO-11395 | H10: MEDINA SILVESTRE GERONIMO | I10: 06279020 | J10: GUTARRA PAUCAR JULIA KARINA | K10: CLÍNICA SAN CAMILO | L10: CRISTINA | M10: 0069754 | N10: 997332688 | O10: MEDINA SILVESTRE GERONIMO | P10: 85967 | Q10: OCT DE MACULA | R10: 1 | S10: PRECISA | T10: POR ASIGNAR | U10: INSTITUTO MEDICO QUIRURGICO AREQUIPA S.A | V10: L.CENTRO | W10: LMAGAN | X10: 186.44 | Y10: LN. EXAMENES | Z10: CIAS. DE SEGURO | AA10: CENTRO | AB10: 982673362 | AC10: 0011-0353-0200308107 | AD10: 50
A11: 46176 | B11: Junio | C11: 97912 | D11: BO | E11: 11395 | F11: CO | G11: BO-11395 | H11: MEDINA SILVESTRE GERONIMO | I11: 06279020 | J11: GUTARRA PAUCAR JULIA KARINA | K11: CLÍNICA SAN CAMILO | L11: CRISTINA | M11: 0069754 | N11: 997332688 | O11: MEDINA SILVESTRE GERONIMO | P11: 85967 | Q11: OCT DE NERVIO OPTICO Y CELULAS GANGLION | R11: 1 | S11: PRECISA | T11: POR ASIGNAR | U11: INSTITUTO MEDICO QUIRURGICO AREQUIPA S.A | V11: L.CENTRO | W11: LMAGAN | X11: 186.44 | Y11: LN. EXAMENES | Z11: CIAS. DE SEGURO | AA11: CENTRO | AB11: 982673362 | AC11: 0011-0353-0200308107 | AD11: 50
A12: 46176 | B12: Junio | C12: 97956 | D12: BO | E12: 11402 | F12: CO | G12: BO-11402 | H12: GARCIA DE SANCHEZ MATILDE | I12: 27062832 | J12: GUTARRA PAUCAR JULIA KARINA | K12: CLÍNICA SAN CAMILO | L12: CRISTINA | M12: 0069790 | N12: 917095913 | O12: GARCIA DE SANCHEZ MATILDE | P12: 86014 | Q12: OCT DE MACULA | R12: 1 | S12: PRECISA | T12: POR ASIGNAR | U12: INSTITUTO MEDICO QUIRURGICO AREQUIPA S.A | V12: L.CENTRO | W12: LMAGAN | X12: 186.44 | Y12: LN. EXAMENES | Z12: CIAS. DE SEGURO | AA12: CENTRO | AB12: 982673362 | AC12: 0011-0353-0200308107 | AD12: 50
A13: 46176 | B13: Junio | C13: 97956 | D13: BO | E13: 11402 | F13: CO | G13: BO-11402 | H13: GARCIA DE SANCHEZ MATILDE | I13: 27062832 | J13: GUTARRA PAUCAR JULIA KARINA | K13: CLÍNICA SAN CAMILO | L13: CRISTINA | M13: 0069790 | N13: 917095913 | O13: GARCIA DE SANCHEZ MATILDE | P13: 86014 | Q13: OCT DE NERVIO OPTICO Y CELULAS GANGLION | R13: 1 | S13: PRECISA | T13: POR ASIGNAR | U13: INSTITUTO MEDICO QUIRURGICO AREQUIPA S.A | V13: L.CENTRO | W13: LMAGAN | X13: 186.44 | Y13: LN. EXAMENES | Z13: CIAS. DE SEGURO | AA13: CENTRO | AB13: 982673362 | AC13: 0011-0353-0200308107 | AD13: 50
A14: 46176 | B14: Junio | C14: 97979 | D14: BO | E14: 11406 | F14: CO | G14: BO-11406 | H14: PEREZ SANCHEZ GIOVANNA MARIELA | I14: 25792949 | J14: BOBBIO PEREZ MILKO | K14: CONSULTORIO | L14: CRISTINA | M14: 0069797 | N14: 946068386 | O14: PEREZ SANCHEZ GIOVANNA MARIELA | P14: 86027 | Q14: OCT DE MACULA | R14: 1 | S14: PRECISA | T14: POR ASIGNAR | U14: INSTITUTO MEDICO QUIRURGICO AREQUIPA S.A | V14: L.CENTRO | W14: LMAGAN | X14: 186.44 | Y14: LN. EXAMENES | Z14: CIAS. DE SEGURO | AA14: CENTRO | AB14: 981214114 | AC14: 191-98432106068 | AD14: 50
A15: 46176 | B15: Junio | C15: 97979 | D15: BO | E15: 11406 | F15: CO | G15: BO-11406 | H15: PEREZ SANCHEZ GIOVANNA MARIELA | I15: 25792949 | J15: BOBBIO PEREZ MILKO | K15: CONSULTORIO | L15: CRISTINA | M15: 0069797 | N15: 946068386 | O15: PEREZ SANCHEZ GIOVANNA MARIELA | P15: 86027 | Q15: PAQUIMETRIA | R15: 1 | S15: PRECISA | T15: POR ASIGNAR | U15: INSTITUTO MEDICO QUIRURGICO AREQUIPA S.A | V15: L.CENTRO | W15: LMAGAN | X15: 152.54 | Y15: LN. EXAMENES | Z15: CIAS. DE SEGURO | AA15: CENTRO | AB15: 981214114 | AC15: 191-98432106068 | AD15: 30
A16: 46177 | B16: Junio | C16: 98036 | D16: BO | E16: 5516 | F16: CO | G16: BO-5516 | H16: PICO DE CRUZADO LUZ EMILIA | I16: 16550311 | J16: AGRAMONTE ZEA EDILBERTO | K16: HOSPITAL DE LA SOLIDARIDAD SJL | L16: CRISTINA | M16: 0069819 | N16: 985411444 | O16: PICO DE CRUZADO LUZ EMILIA | P16: 86087 | Q16: OCT DE MACULA | R16: 1 | S16: PRECISA | T16: POR ASIGNAR | U16: INSTITUTO MEDICO QUIRURGICO AREQUIPA S.A | V16: L.CENTRO | W16: ACABRERA | X16: 186.44 | Y16: LN. EXAMENES | Z16: CIAS. DE SEGURO | AA16: CENTRO | AB16: 987407712 | AC16: 0011-0190-0200333106 | AD16: 50
A17: 46177 | B17: Junio | C17: 98044 | D17: BO | E17: 11419 | F17: CO | G17: BO-11419 | H17: SACHA NAVARRO GERARDO JUNIOR | I17: 47180662 | J17: CACERES PINTO ALVARO DANIEL | K17: HOSPITAL INO | L17: CRISTINA | M17: 0069825 | N17: 958365826 | O17: SACHA NAVARRO GERARDO JUNIOR | P17: 86096 | Q17: FOTOCLINICA EN MOSAICO | R17: 1 | S17: PRECISA | T17: POR ASIGNAR | U17: INSTITUTO MEDICO QUIRURGICO AREQUIPA S.A | V17: L.CENTRO | W17: LMAGAN | X17: 169.49 | Y17: LN. EXAMENES | Z17: CIAS. DE SEGURO | AA17: CENTRO | AB17: 966697811 | AC17: 0011-0184-0200649518 | AD17: 50
A18: 46177 | B18: Junio | C18: 98044 | D18: BO | E18: 11419 | F18: CO | G18: BO-11419 | H18: SACHA NAVARRO GERARDO JUNIOR | I18: 47180662 | J18: CACERES PINTO ALVARO DANIEL | K18: HOSPITAL INO | L18: CRISTINA | M18: 0069825 | N18: 958365826 | O18: SACHA NAVARRO GERARDO JUNIOR | P18: 86096 | Q18: OCT DE MACULA | R18: 1 | S18: PRECISA | T18: POR ASIGNAR | U18: INSTITUTO MEDICO QUIRURGICO AREQUIPA S.A | V18: L.CENTRO | W18: LMAGAN | X18: 186.44 | Y18: LN. EXAMENES | Z18: CIAS. DE SEGURO | AA18: CENTRO | AB18: 966697811 | AC18: 0011-0184-0200649518 | AD18: 50
A19: 46177 | B19: Junio | C19: 98044 | D19: BO | E19: 11419 | F19: CO | G19: BO-11419 | H19: SACHA NAVARRO GERARDO JUNIOR | I19: 47180662 | J19: CACERES PINTO ALVARO DANIEL | K19: HOSPITAL INO | L19: CRISTINA | M19: 0069825 | N19: 958365826 | O19: SACHA NAVARRO GERARDO JUNIOR | P19: 86096 | Q19: OCT DE NERVIO OPTICO Y CELULAS GANGLION | R19: 1 | S19: PRECISA | T19: POR ASIGNAR | U19: INSTITUTO MEDICO QUIRURGICO AREQUIPA S.A | V19: L.CENTRO | W19: LMAGAN | X19: 186.44 | Y19: LN. EXAMENES | Z19: CIAS. DE SEGURO | AA19: CENTRO | AB19: 966697811 | AC19: 0011-0184-0200649518 | AD19: 50
A20: 46177 | B20: Junio | C20: 98041 | D20: FA | E20: 1025 | F20: CO | G20: FA-1025 | H20: NUÑEZ ALTIS ANTONIO SALOMON | I20: 09498424 | J20: VILLAR CURAHUA MARCELA ALEJANDRA | K20: GAMARRA SALUD | L20: CRISTINA | M20: 0069549 | N20: 928076253 | O20: GAMARRA HEALTHCARE CENTER S.A.C. | P20: 86093 | Q20: BIOMETRIA IOL MASTER 700 | R20: 1 | S20: PRECISA | T20: POR ASIGNAR | U20: INSTITUTO MEDICO QUIRURGICO AREQUIPA S.A | V20: L.CENTRO | W20: LMAGAN | X20: 152.54 | Y20: LN. EXAMENES | Z20: CIAS. DE SEGURO | AA20: CENTRO | AB20: 950133748 | AC20: 191-9953047026 | AD20: 30
A21: 46177 | B21: Junio | C21: 98041 | D21: FA | E21: 1025 | F21: CO | G21: FA-1025 | H21: NUÑEZ ALTIS ANTONIO SALOMON | I21: 09498424 | J21: VILLAR CURAHUA MARCELA ALEJANDRA | K21: GAMARRA SALUD | L21: CRISTINA | M21: 0069549 | N21: 928076253 | O21: GAMARRA HEALTHCARE CENTER S.A.C. | P21: 86093 | Q21: MICROSCOPIA ESPECULAR | R21: 1 | S21: PRECISA | T21: POR ASIGNAR | U21: INSTITUTO MEDICO QUIRURGICO AREQUIPA S.A | V21: L.CENTRO | W21: LMAGAN | X21: 135.59 | Y21: LN. EXAMENES | Z21: CIAS. DE SEGURO | AA21: CENTRO | AB21: 950133748 | AC21: 191-9953047026 | AD21: 30
A22: 46177 | B22: Junio | C22: 98051 | D22: FA | E22: 524 | F22: CO | G22: FA-524 | H22: GARCIA RICO ELVA JOSEFINA | I22: 16408791 | J22: VILLAR CURAHUA MARCELA ALEJANDRA | K22: GAMARRA SALUD | L22: CRISTINA | M22: 0067849 | N22: 902449032 | O22: GAMARRA HEALTHCARE CENTER S.A.C. | P22: 85864 | Q22: CIRUGIA DE DIA | R22: 1 | S22: PRECISA | T22: POR ASIGNAR | U22: INSTITUTO MEDICO QUIRURGICO AREQUIPA S.A | V22: L.CENTRO | W22: ACABRERA | X22: 0 | Y22: LN. CIRUGIA | Z22: CIAS. DE SEGURO | AA22: CENTRO | AB22: 950133748 | AC22: 191-9953047026
A23: 46177 | B23: Junio | C23: 98051 | D23: FA | E23: 524 | F23: CO | G23: FA-524 | H23: GARCIA RICO ELVA JOSEFINA | I23: 16408791 | J23: VILLAR CURAHUA MARCELA ALEJANDRA | K23: GAMARRA SALUD | L23: CRISTINA | M23: 0067849 | N23: 902449032 | O23: GAMARRA HEALTHCARE CENTER S.A.C. | P23: 85864 | Q23: FACOEMULSIFICACION PRIMIUM | R23: 1 | S23: PRECISA | T23: POR ASIGNAR | U23: INSTITUTO MEDICO QUIRURGICO AREQUIPA S.A | V23: L.CENTRO | W23: ACABRERA | X23: 1050.85 | Y23: LN. CIRUGIA | Z23: CIAS. DE SEGURO | AA23: CENTRO | AB23: 950133748 | AC23: 191-9953047026
A24: 46177 | B24: Junio | C24: 98052 | D24: FA | E24: 525 | F24: CO | G24: FA-525 | H24: NUÑEZ ALTIS ANTONIO SALOMON | I24: 09498424 | J24: VILLAR CURAHUA MARCELA ALEJANDRA | K24: GAMARRA SALUD | L24: CRISTINA | M24: 0069549 | N24: 928076253 | O24: GAMARRA HEALTHCARE CENTER S.A.C. | P24: 85863 | Q24: CIRUGIA DE DIA | R24: 1 | S24: PRECISA | T24: POR ASIGNAR | U24: INSTITUTO MEDICO QUIRURGICO AREQUIPA S.A | V24: L.CENTRO | W24: ACABRERA | X24: 0 | Y24: LN. CIRUGIA | Z24: CIAS. DE SEGURO | AA24: CENTRO | AB24: 950133748 | AC24: 191-9953047026
A25: 46177 | B25: Junio | C25: 98052 | D25: FA | E25: 525 | F25: CO | G25: FA-525 | H25: NUÑEZ ALTIS ANTONIO SALOMON | I25: 09498424 | J25: VILLAR CURAHUA MARCELA ALEJANDRA | K25: GAMARRA SALUD | L25: CRISTINA | M25: 0069549 | N25: 928076253 | O25: GAMARRA HEALTHCARE CENTER S.A.C. | P25: 85863 | Q25: FACOEMULSIFICACION PRIMIUM | R25: 1 | S25: PRECISA | T25: POR ASIGNAR | U25: INSTITUTO MEDICO QUIRURGICO AREQUIPA S.A | V25: L.CENTRO | W25: ACABRERA | X25: 1050.85 | Y25: LN. CIRUGIA | Z25: CIAS. DE SEGURO | AA25: CENTRO | AB25: 950133748 | AC25: 191-9953047026
A26: 46177 | B26: Junio | C26: 98035 | D26: BO | E26: 4221 | F26: CO | G26: BO-4221 | H26: PEÑA GARCIA BENIGNO OSCAR | I26: 48945300 | J26: RUIZ ROJAS PAUBLO ENRIQUE | K26: CONSULTORIO CUBANO COMAS | L26: CRISTINA | M26: 0069818 | N26: 922009271 | O26: PEÑA GARCIA BENIGNO OSCAR | P26: 86086 | Q26: OCT DE MACULA | R26: 1 | S26: PRECISA LN | T26: POR ASIGNAR | U26: INSTITUTO MEDICO QUIRURGICO AREQUIPA S.A | V26: L.NORTE | W26: AALARCON | X26: 186.44 | Y26: LN. EXAMENES | Z26: CIAS. DE SEGURO | AA26: NORTE | AB26: 992903716 | AC26: 191-91415089071 | AD26: 50
A27: 46177 | B27: Junio | C27: 98035 | D27: BO | E27: 4221 | F27: CO | G27: BO-4221 | H27: PEÑA GARCIA BENIGNO OSCAR | I27: 48945300 | J27: RUIZ ROJAS PAUBLO ENRIQUE | K27: CONSULTORIO CUBANO COMAS | L27: CRISTINA | M27: 0069818 | N27: 922009271 | O27: PEÑA GARCIA BENIGNO OSCAR | P27: 86086 | Q27: OCT DE NERVIO OPTICO Y CELULAS GANGLION | R27: 1 | S27: PRECISA LN | T27: POR ASIGNAR | U27: INSTITUTO MEDICO QUIRURGICO AREQUIPA S.A | V27: L.NORTE | W27: AALARCON | X27: 186.44 | Y27: LN. EXAMENES | Z27: CIAS. DE SEGURO | AA27: NORTE | AB27: 992903716 | AC27: 191-91415089071 | AD27: 50
A28: 46178 | B28: Junio | C28: 98106 | D28: BO | E28: 5526 | F28: CO | G28: BO-5526 | H28: VALERA BAZAN LAURA PIERI | I28: 08013693 | J28: CASTRO TAMANAJA VANIA VIVIAN | K28: HOSPITAL 2 DE MAYO | L28: CRISTINA | M28: 0056253 | N28: 4715484 | O28: VALERA BAZAN LAURA PIERI | P28: 86151 | Q28: OCT DE NERVIO OPTICO Y CELULAS GANGLION | R28: 1 | S28: PRECISA | T28: POR ASIGNAR | U28: INSTITUTO MEDICO QUIRURGICO AREQUIPA S.A | V28: L.CENTRO | W28: ACABRERA | X28: 186.44 | Y28: LN. EXAMENES | Z28: CIAS. DE SEGURO | AA28: CENTRO | AB28: 986661693 | AC28: 0011-0354-0200096288 | AD28: 50
A29: 46178 | B29: Junio | C29: 2353 | D29: NC | E29: 5527 | F29: CR | G29: NC-5527 | H29: BRAVO QUISPE VDA DE ANDIA ANGELICA RITA | I29: 07412423 | J29: FERNANDEZ GUTIERREZ OLGA PATRICIA | K29: CONSULTORIO PARTICULAR | L29: CR | M29: 0069850 | N29: 979750580 | O29: BRAVO QUISPE VDA DE ANDIA ANGELICA RITA | P29: 86154 | Q29: USO DE EQUIPOS E INSUMO IRIDOTOMIA | R29: 2 | S29: PRECISA | T29: POR ASIGNAR | U29: INSTITUTO MEDICO QUIRURGICO AREQUIPA S.A | V29: L.CENTRO | W29: ACABRERA | X29: -203.39 | Y29: LN. PROCEDIMIENTO | Z29: CIAS. DE SEGURO | AA29: CENTRO | AB29: 982536223 | AC29: 107-3174605363
A30: 46178 | B30: Junio | C30: 98110 | D30: FA | E30: 527 | F30: CO | G30: FA-527 | H30: BRAVO QUISPE VDA DE ANDIA ANGELICA RITA | I30: 07412423 | J30: FERNANDEZ GUTIERREZ OLGA PATRICIA | K30: CONSULTORIO PARTICULAR | L30: CRISTINA | M30: 0069850 | N30: 979750580 | O30: VEFER OFTALMOLOGOS S.A.C. | P30: 86155 | Q30: USO DE EQUIPOS E INSUMO IRIDOTOMIA | R30: 2 | S30: PRECISA | T30: POR ASIGNAR | U30: INSTITUTO MEDICO QUIRURGICO AREQUIPA S.A | V30: L.CENTRO | W30: ACABRERA | X30: 203.39 | Y30: LN. PROCEDIMIENTO | Z30: CIAS. DE SEGURO | AA30: CENTRO | AB30: 982536223 | AC30: 107-3174605363
A31: 46178 | B31: Junio | C31: 2353 | D31: BO | E31: 5527 | F31: CR | G31: BO-5527 | H31: BRAVO QUISPE VDA DE ANDIA ANGELICA RITA | I31: 07412423 | J31: FERNANDEZ GUTIERREZ OLGA PATRICIA | K31: CONSULTORIO PARTICULAR | L31: CR | M31: 0069850 | N31: 979750580 | O31: BRAVO QUISPE VDA DE ANDIA ANGELICA RITA | P31: 86154 | Q31: USO DE EQUIPOS E INSUMO IRIDOTOMIA | R31: 2 | S31: PRECISA | T31: POR ASIGNAR | U31: INSTITUTO MEDICO QUIRURGICO AREQUIPA S.A | V31: L.CENTRO | W31: ACABRERA | X31: 203.39 | Y31: LN. PROCEDIMIENTO | Z31: CIAS. DE SEGURO | AA31: CENTRO | AB31: 982536223 | AC31: 107-3174605363
A32: 46178 | B32: Junio | C32: 98108 | D32: FA | E32: 526 | F32: CO | G32: FA-526 | H32: ABAD OVALLE ARLINE MERCEDES | I32: 25532349 | L32: CRISTINA | M32: 0069694 | N32: 999999452 | O32: VEFER OFTALMOLOGOS S.A.C. | P32: 86152 | Q32: USO DE EQUIPOS E INSUMO IRIDOTOMIA | R32: 2 | S32: PRECISA | T32: POR ASIGNAR | U32: INSTITUTO MEDICO QUIRURGICO AREQUIPA S.A | V32: L.CENTRO | W32: ACABRERA | X32: 203.39 | Y32: LN. PROCEDIMIENTO | Z32: CIAS. DE SEGURO | AA32: CENTRO
A33: 46179 | B33: Junio | C33: 98152 | D33: BO | E33: 4244 | F33: CO | G33: BO-4244 | H33: OLIVO CASTRO JULIA GLADYS | I33: 15292242 | J33: RUIZ ROJAS PAUBLO ENRIQUE | K33: CONSULTORIO CUBANO COMAS | L33: CRISTINA | M33: 0069884 | N33: 952190646 | O33: OLIVO CASTRO JULIA GLADYS | P33: 86190 | Q33: OCT DE MACULA | R33: 1 | S33: PRECISA LN | T33: POR ASIGNAR | U33: INSTITUTO MEDICO QUIRURGICO AREQUIPA S.A | V33: L.NORTE | W33: AALARCON | X33: 186.44 | Y33: LN. EXAMENES | Z33: CIAS. DE SEGURO | AA33: NORTE | AB33: 992903716 | AC33: 191-91415089071 | AD33: 50
A34: 46179 | B34: Junio | C34: 98151 | D34: BO | E34: 11423 | F34: CO | G34: BO-11423 | H34: PACACHA FLORES BLANCA VALESKA | I34: 91733805 | J34: CRISPIN MORALES NANCY JENNY | K34: HOSPITAL ALMENARA | L34: CRISTINA | M34: 0069883 | N34: 970593962 | O34: PACACHA FLORES BLANCA VALESKA | P34: 86188 | Q34: TOPOGRAFIA CORNEAL | R34: 1 | S34: PRECISA | T34: POR ASIGNAR | U34: INSTITUTO MEDICO QUIRURGICO AREQUIPA S.A | V34: L.CENTRO | W34: LMAGAN | X34: 152.54 | Y34: LN. EXAMENES | Z34: CIAS. DE SEGURO | AA34: CENTRO | AB34: 978789268 | AC34: 193-90416675072 | AD34: 30
A35: 46179 | B35: Junio | C35: 98176 | D35: BO | E35: 11428 | F35: CO | G35: BO-11428 | H35: REYES SANCHEZ OLGA EULALIA | I35: 09330262 | J35: LLERENA MORALES OSCAR ADOLFO | K35: SANNA SAN MIGUEL | L35: CRISTINA | M35: 0069894 | N35: 947513770 | O35: REYES SANCHEZ OLGA EULALIA | P35: 86218 | Q35: CAMPIMETRIA (CAMPO VISUAL) | R35: 1 | S35: PRECISA | T35: POR ASIGNAR | U35: INSTITUTO MEDICO QUIRURGICO AREQUIPA S.A | V35: L.CENTRO | W35: LMAGAN | X35: 135.59 | Y35: LN. EXAMENES | Z35: CIAS. DE SEGURO | AA35: CENTRO | AB35: 987552890 | AC35: 098-7304409 | AD35: 30
A36: 46179 | B36: Junio | C36: 98176 | D36: BO | E36: 11428 | F36: CO | G36: BO-11428 | H36: REYES SANCHEZ OLGA EULALIA | I36: 09330262 | J36: LLERENA MORALES OSCAR ADOLFO | K36: SANNA SAN MIGUEL | L36: CRISTINA | M36: 0069894 | N36: 947513770 | O36: REYES SANCHEZ OLGA EULALIA | P36: 86218 | Q36: PAQUIMETRIA | R36: 1 | S36: PRECISA | T36: POR ASIGNAR | U36: INSTITUTO MEDICO QUIRURGICO AREQUIPA S.A | V36: L.CENTRO | W36: LMAGAN | X36: 152.54 | Y36: LN. EXAMENES | Z36: CIAS. DE SEGURO | AA36: CENTRO | AB36: 987552890 | AC36: 098-7304409 | AD36: 30
A37: 46179 | B37: Junio | C37: 98176 | D37: BO | E37: 11428 | F37: CO | G37: BO-11428 | H37: REYES SANCHEZ OLGA EULALIA | I37: 09330262 | J37: LLERENA MORALES OSCAR ADOLFO | K37: SANNA SAN MIGUEL | L37: CRISTINA | M37: 0069894 | N37: 947513770 | O37: REYES SANCHEZ OLGA EULALIA | P37: 86218 | Q37: OCT DE NERVIO OPTICO Y CELULAS GANGLION | R37: 1 | S37: PRECISA | T37: POR ASIGNAR | U37: INSTITUTO MEDICO QUIRURGICO AREQUIPA S.A | V37: L.CENTRO | W37: LMAGAN | X37: 186.44 | Y37: LN. EXAMENES | Z37: CIAS. DE SEGURO | AA37: CENTRO | AB37: 987552890 | AC37: 098-7304409 | AD37: 50
A38: 46179 | B38: Junio | C38: 98167 | D38: BO | E38: 4250 | F38: CO | G38: BO-4250 | H38: RONCAL ROMERO FANNYNG EDITH | I38: 44905743 | J38: ROJAS AQUINO EVELING KARINA | K38: POLICLÍNICO ESPÍRITU SANTO | L38: CRISTINA | M38: 0069844 | N38: 984441413 | O38: RONCAL ROMERO FANNYNG EDITH | P38: 86210 | Q38: OCT DE NERVIO OPTICO Y CELULAS GANGLION | R38: 1 | S38: PRECISA LN | T38: POR ASIGNAR | U38: INSTITUTO MEDICO QUIRURGICO AREQUIPA S.A | V38: L.NORTE | W38: AALARCON | X38: 186.44 | Y38: LN. EXAMENES | Z38: CIAS. DE SEGURO | AA38: NORTE | AB38: 955356636 | AC38: 009-3226956615 | AD38: 50
A39: 46182 | B39: Junio | C39: 98452 | D39: FA | E39: 532 | F39: CO | G39: FA-532 | H39: BENITES RAMOS ANTENOR HERMAN | I39: 07187063 | J39: VILLAR CURAHUA MARCELA ALEJANDRA | K39: GAMARRA SALUD | L39: CRISTINA | M39: 0069415 | N39: 943410784 | O39: GAMARRA HEALTHCARE CENTER S.A.C. | P39: 86345 | Q39: CIRUGIA DE DIA | R39: 1 | S39: PRECISA | T39: POR ASIGNAR | U39: INSTITUTO MEDICO QUIRURGICO AREQUIPA S.A | V39: L.CENTRO | W39: ACABRERA | X39: 0 | Y39: LN. CIRUGIA | Z39: CIAS. DE SEGURO | AA39: CENTRO | AB39: 950133748 | AC39: 191-9953047026
A40: 46182 | B40: Junio | C40: 98452 | D40: FA | E40: 532 | F40: CO | G40: FA-532 | H40: BENITES RAMOS ANTENOR HERMAN | I40: 07187063 | J40: VILLAR CURAHUA MARCELA ALEJANDRA | K40: GAMARRA SALUD | L40: CRISTINA | M40: 0069415 | N40: 943410784 | O40: GAMARRA HEALTHCARE CENTER S.A.C. | P40: 86345 | Q40: FACOEMULSIFICACION PRIMIUM | R40: 1 | S40: PRECISA | T40: POR ASIGNAR | U40: INSTITUTO MEDICO QUIRURGICO AREQUIPA S.A | V40: L.CENTRO | W40: ACABRERA | X40: 1050.85 | Y40: LN. CIRUGIA | Z40: CIAS. DE SEGURO | AA40: CENTRO | AB40: 950133748 | AC40: 191-9953047026
...

Sheet Cálculo_Categorías
A1: REPORTE DE FACTURACIÓN Y CATEGORIZACIÓN MÉDICO/INSTITUCIÓN
A3: Filtro de Mes | C3: S/. | E3: Filtro de Mes | G3: S/.
A4: Mes | B4: TODOS | C4: =+SUM(Tabla5[FACTURACIÓN]) -> 166117.68 | E4: Mes | F4: TODOS | G4: =+SUM(Tabla9[FACTURACIÓN]) -> 165507.54
A6: REPORTE DE MÉDICOS Y CATEGORIZACIÓN | E6: REPORTE DE INSTITUCIONES Y CATEGORIZACIÓN
A7: MEDICO | B7: FACTURACIÓN | C7: CATEGORÍA | E7: INSTITUCIÓN | F7: FACTURACIÓN | G7: CATEGORÍA
A8: ORNA ACOSTA JORGE AQUILES | B8: =+IF($B$4="TODOS",SUMIFS(Base_Precisa!X:X,Base_Precisa!J:J,Cálculo_Categorías!A8),SUMIFS(Base_Precisa!X:X,Base_Precisa!J:J,Cálculo_Categorías!A8,Base_Precisa!B:B,Cálculo_Categorías!$B$4)) -> 1271.17 | C8: {=+_xlfn.IFS(Tabla5[[#This Row],[FACTURACIÓN]]<500,"A",Tabla5[[#This Row],[FACTURACIÓN]]<1000,"AA",Tabla5[[#This Row],[FACTURACIÓN]]>=1000,"AAA")} -> AAA | E8: HOSPITAL LOAYZA | F8: =+IF($F$4="TODOS",SUMIFS(Base_Precisa!X:X,Base_Precisa!K:K,Cálculo_Categorías!E8),SUMIFS(Base_Precisa!X:X,Base_Precisa!K:K,Cálculo_Categorías!E8,Base_Precisa!B:B,Cálculo_Categorías!$F$4)) -> 12203.24 | G8: {=+_xlfn.IFS(Tabla9[[#This Row],[FACTURACIÓN]]<200,"Sin Categoría",Tabla9[[#This Row],[FACTURACIÓN]]<500,"A",Tabla9[[#This Row],[FACTURACIÓN]]<1000,"AA",Tabla9[[#This Row],[FACTURACIÓN]]>=1000,"AAA")} -> AAA
A9: PEÑA CAMARGO CRISTOPHER OMAR | B9: =+IF($B$4="TODOS",SUMIFS(Base_Precisa!X:X,Base_Precisa!J:J,Cálculo_Categorías!A9),SUMIFS(Base_Precisa!X:X,Base_Precisa!J:J,Cálculo_Categorías!A9,Base_Precisa!B:B,Cálculo_Categorías!$B$4)) -> 372.88 | C9: {=+_xlfn.IFS(Tabla5[[#This Row],[FACTURACIÓN]]<500,"A",Tabla5[[#This Row],[FACTURACIÓN]]<1000,"AA",Tabla5[[#This Row],[FACTURACIÓN]]>=1000,"AAA")} -> A | E9: HOSPITAL SERGIO BERNALES | F9: =+IF($F$4="TODOS",SUMIFS(Base_Precisa!X:X,Base_Precisa!K:K,Cálculo_Categorías!E9),SUMIFS(Base_Precisa!X:X,Base_Precisa!K:K,Cálculo_Categorías!E9,Base_Precisa!B:B,Cálculo_Categorías!$F$4)) -> 1779.64 | G9: {=+_xlfn.IFS(Tabla9[[#This Row],[FACTURACIÓN]]<200,"Sin Categoría",Tabla9[[#This Row],[FACTURACIÓN]]<500,"A",Tabla9[[#This Row],[FACTURACIÓN]]<1000,"AA",Tabla9[[#This Row],[FACTURACIÓN]]>=1000,"AAA")} -> AAA
A10: TORRES LEAL ADOLFO LEON | B10: =+IF($B$4="TODOS",SUMIFS(Base_Precisa!X:X,Base_Precisa!J:J,Cálculo_Categorías!A10),SUMIFS(Base_Precisa!X:X,Base_Precisa!J:J,Cálculo_Categorías!A10,Base_Precisa!B:B,Cálculo_Categorías!$B$4)) -> 271.18 | C10: {=+_xlfn.IFS(Tabla5[[#This Row],[FACTURACIÓN]]<500,"A",Tabla5[[#This Row],[FACTURACIÓN]]<1000,"AA",Tabla5[[#This Row],[FACTURACIÓN]]>=1000,"AAA")} -> A | E10: CLÍNICA SAN FELIPE LA MOLINA | F10: =+IF($F$4="TODOS",SUMIFS(Base_Precisa!X:X,Base_Precisa!K:K,Cálculo_Categorías!E10),SUMIFS(Base_Precisa!X:X,Base_Precisa!K:K,Cálculo_Categorías!E10,Base_Precisa!B:B,Cálculo_Categorías!$F$4)) -> 271.18 | G10: {=+_xlfn.IFS(Tabla9[[#This Row],[FACTURACIÓN]]<200,"Sin Categoría",Tabla9[[#This Row],[FACTURACIÓN]]<500,"A",Tabla9[[#This Row],[FACTURACIÓN]]<1000,"AA",Tabla9[[#This Row],[FACTURACIÓN]]>=1000,"AAA")} -> A
A11: HUARANGA RUIZ CORNEJO JORGE ERNESTO | B11: =+IF($B$4="TODOS",SUMIFS(Base_Precisa!X:X,Base_Precisa!J:J,Cálculo_Categorías!A11),SUMIFS(Base_Precisa!X:X,Base_Precisa!J:J,Cálculo_Categorías!A11,Base_Precisa!B:B,Cálculo_Categorías!$B$4)) -> 898.29 | C11: {=+_xlfn.IFS(Tabla5[[#This Row],[FACTURACIÓN]]<500,"A",Tabla5[[#This Row],[FACTURACIÓN]]<1000,"AA",Tabla5[[#This Row],[FACTURACIÓN]]>=1000,"AAA")} -> AA | E11: HOSPITAL MONGRUT | F11: =+IF($F$4="TODOS",SUMIFS(Base_Precisa!X:X,Base_Precisa!K:K,Cálculo_Categorías!E11),SUMIFS(Base_Precisa!X:X,Base_Precisa!K:K,Cálculo_Categorías!E11,Base_Precisa!B:B,Cálculo_Categorías!$F$4)) -> 898.29 | G11: {=+_xlfn.IFS(Tabla9[[#This Row],[FACTURACIÓN]]<200,"Sin Categoría",Tabla9[[#This Row],[FACTURACIÓN]]<500,"A",Tabla9[[#This Row],[FACTURACIÓN]]<1000,"AA",Tabla9[[#This Row],[FACTURACIÓN]]>=1000,"AAA")} -> AA
A12: AGRAMONTE ZEA EDILBERTO | B12: =+IF($B$4="TODOS",SUMIFS(Base_Precisa!X:X,Base_Precisa!J:J,Cálculo_Categorías!A12),SUMIFS(Base_Precisa!X:X,Base_Precisa!J:J,Cálculo_Categorías!A12,Base_Precisa!B:B,Cálculo_Categorías!$B$4)) -> 4338.93 | C12: {=+_xlfn.IFS(Tabla5[[#This Row],[FACTURACIÓN]]<500,"A",Tabla5[[#This Row],[FACTURACIÓN]]<1000,"AA",Tabla5[[#This Row],[FACTURACIÓN]]>=1000,"AAA")} -> AAA | E12: HOSPITAL DE LA SOLIDARIDAD SJL | F12: =+IF($F$4="TODOS",SUMIFS(Base_Precisa!X:X,Base_Precisa!K:K,Cálculo_Categorías!E12),SUMIFS(Base_Precisa!X:X,Base_Precisa!K:K,Cálculo_Categorías!E12,Base_Precisa!B:B,Cálculo_Categorías!$F$4)) -> 4338.93 | G12: {=+_xlfn.IFS(Tabla9[[#This Row],[FACTURACIÓN]]<200,"Sin Categoría",Tabla9[[#This Row],[FACTURACIÓN]]<500,"A",Tabla9[[#This Row],[FACTURACIÓN]]<1000,"AA",Tabla9[[#This Row],[FACTURACIÓN]]>=1000,"AAA")} -> AAA
A13: MANSILLA JUAN JOSÉ | B13: =+IF($B$4="TODOS",SUMIFS(Base_Precisa!X:X,Base_Precisa!J:J,Cálculo_Categorías!A13),SUMIFS(Base_Precisa!X:X,Base_Precisa!J:J,Cálculo_Categorías!A13,Base_Precisa!B:B,Cálculo_Categorías!$B$4)) -> 355.93 | C13: {=+_xlfn.IFS(Tabla5[[#This Row],[FACTURACIÓN]]<500,"A",Tabla5[[#This Row],[FACTURACIÓN]]<1000,"AA",Tabla5[[#This Row],[FACTURACIÓN]]>=1000,"AAA")} -> A | E13: CONSULTORIO PARTICULAR | F13: =+IF($F$4="TODOS",SUMIFS(Base_Precisa!X:X,Base_Precisa!K:K,Cálculo_Categorías!E13),SUMIFS(Base_Precisa!X:X,Base_Precisa!K:K,Cálculo_Categorías!E13,Base_Precisa!B:B,Cálculo_Categorías!$F$4)) -> 21639.64 | G13: {=+_xlfn.IFS(Tabla9[[#This Row],[FACTURACIÓN]]<200,"Sin Categoría",Tabla9[[#This Row],[FACTURACIÓN]]<500,"A",Tabla9[[#This Row],[FACTURACIÓN]]<1000,"AA",Tabla9[[#This Row],[FACTURACIÓN]]>=1000,"AAA")} -> AAA
A14: CELIA RODRIGUEZ | B14: =+IF($B$4="TODOS",SUMIFS(Base_Precisa!X:X,Base_Precisa!J:J,Cálculo_Categorías!A14),SUMIFS(Base_Precisa!X:X,Base_Precisa!J:J,Cálculo_Categorías!A14,Base_Precisa!B:B,Cálculo_Categorías!$B$4)) -> 0 | C14: {=+_xlfn.IFS(Tabla5[[#This Row],[FACTURACIÓN]]<500,"A",Tabla5[[#This Row],[FACTURACIÓN]]<1000,"AA",Tabla5[[#This Row],[FACTURACIÓN]]>=1000,"AAA")} -> A | E14: CLÍNICA SAN CAMILO | F14: =+IF($F$4="TODOS",SUMIFS(Base_Precisa!X:X,Base_Precisa!K:K,Cálculo_Categorías!E14),SUMIFS(Base_Precisa!X:X,Base_Precisa!K:K,Cálculo_Categorías!E14,Base_Precisa!B:B,Cálculo_Categorías!$F$4)) -> 3809.29 | G14: {=+_xlfn.IFS(Tabla9[[#This Row],[FACTURACIÓN]]<200,"Sin Categoría",Tabla9[[#This Row],[FACTURACIÓN]]<500,"A",Tabla9[[#This Row],[FACTURACIÓN]]<1000,"AA",Tabla9[[#This Row],[FACTURACIÓN]]>=1000,"AAA")} -> AAA
A15: GUTARRA PAUCAR JULIA KARINA | B15: =+IF($B$4="TODOS",SUMIFS(Base_Precisa!X:X,Base_Precisa!J:J,Cálculo_Categorías!A15),SUMIFS(Base_Precisa!X:X,Base_Precisa!J:J,Cálculo_Categorías!A15,Base_Precisa!B:B,Cálculo_Categorías!$B$4)) -> 3809.29 | C15: {=+_xlfn.IFS(Tabla5[[#This Row],[FACTURACIÓN]]<500,"A",Tabla5[[#This Row],[FACTURACIÓN]]<1000,"AA",Tabla5[[#This Row],[FACTURACIÓN]]>=1000,"AAA")} -> AAA | E15: CONSULTORIO | F15: =+IF($F$4="TODOS",SUMIFS(Base_Precisa!X:X,Base_Precisa!K:K,Cálculo_Categorías!E15),SUMIFS(Base_Precisa!X:X,Base_Precisa!K:K,Cálculo_Categorías!E15,Base_Precisa!B:B,Cálculo_Categorías!$F$4)) -> 1084.74 | G15: {=+_xlfn.IFS(Tabla9[[#This Row],[FACTURACIÓN]]<200,"Sin Categoría",Tabla9[[#This Row],[FACTURACIÓN]]<500,"A",Tabla9[[#This Row],[FACTURACIÓN]]<1000,"AA",Tabla9[[#This Row],[FACTURACIÓN]]>=1000,"AAA")} -> AAA
A16: BOBBIO PEREZ MILKO | B16: =+IF($B$4="TODOS",SUMIFS(Base_Precisa!X:X,Base_Precisa!J:J,Cálculo_Categorías!A16),SUMIFS(Base_Precisa!X:X,Base_Precisa!J:J,Cálculo_Categorías!A16,Base_Precisa!B:B,Cálculo_Categorías!$B$4)) -> 338.98 | C16: {=+_xlfn.IFS(Tabla5[[#This Row],[FACTURACIÓN]]<500,"A",Tabla5[[#This Row],[FACTURACIÓN]]<1000,"AA",Tabla5[[#This Row],[FACTURACIÓN]]>=1000,"AAA")} -> A | E16: HOSPITAL INO | F16: =+IF($F$4="TODOS",SUMIFS(Base_Precisa!X:X,Base_Precisa!K:K,Cálculo_Categorías!E16),SUMIFS(Base_Precisa!X:X,Base_Precisa!K:K,Cálculo_Categorías!E16,Base_Precisa!B:B,Cálculo_Categorías!$F$4)) -> 1322.02 | G16: {=+_xlfn.IFS(Tabla9[[#This Row],[FACTURACIÓN]]<200,"Sin Categoría",Tabla9[[#This Row],[FACTURACIÓN]]<500,"A",Tabla9[[#This Row],[FACTURACIÓN]]<1000,"AA",Tabla9[[#This Row],[FACTURACIÓN]]>=1000,"AAA")} -> AAA
A17: CACERES PINTO ALVARO DANIEL | B17: =+IF($B$4="TODOS",SUMIFS(Base_Precisa!X:X,Base_Precisa!J:J,Cálculo_Categorías!A17),SUMIFS(Base_Precisa!X:X,Base_Precisa!J:J,Cálculo_Categorías!A17,Base_Precisa!B:B,Cálculo_Categorías!$B$4)) -> 881.35 | C17: {=+_xlfn.IFS(Tabla5[[#This Row],[FACTURACIÓN]]<500,"A",Tabla5[[#This Row],[FACTURACIÓN]]<1000,"AA",Tabla5[[#This Row],[FACTURACIÓN]]>=1000,"AAA")} -> AA | E17: GAMARRA SALUD | F17: =+IF($F$4="TODOS",SUMIFS(Base_Precisa!X:X,Base_Precisa!K:K,Cálculo_Categorías!E17),SUMIFS(Base_Precisa!X:X,Base_Precisa!K:K,Cálculo_Categorías!E17,Base_Precisa!B:B,Cálculo_Categorías!$F$4)) -> 30101.66 | G17: {=+_xlfn.IFS(Tabla9[[#This Row],[FACTURACIÓN]]<200,"Sin Categoría",Tabla9[[#This Row],[FACTURACIÓN]]<500,"A",Tabla9[[#This Row],[FACTURACIÓN]]<1000,"AA",Tabla9[[#This Row],[FACTURACIÓN]]>=1000,"AAA")} -> AAA
A18: VILLAR CURAHUA MARCELA ALEJANDRA | B18: =+IF($B$4="TODOS",SUMIFS(Base_Precisa!X:X,Base_Precisa!J:J,Cálculo_Categorías!A18),SUMIFS(Base_Precisa!X:X,Base_Precisa!J:J,Cálculo_Categorías!A18,Base_Precisa!B:B,Cálculo_Categorías!$B$4)) -> 30101.66 | C18: {=+_xlfn.IFS(Tabla5[[#This Row],[FACTURACIÓN]]<500,"A",Tabla5[[#This Row],[FACTURACIÓN]]<1000,"AA",Tabla5[[#This Row],[FACTURACIÓN]]>=1000,"AAA")} -> AAA | E18: CONSULTORIO CUBANO COMAS | F18: =+IF($F$4="TODOS",SUMIFS(Base_Precisa!X:X,Base_Precisa!K:K,Cálculo_Categorías!E18),SUMIFS(Base_Precisa!X:X,Base_Precisa!K:K,Cálculo_Categorías!E18,Base_Precisa!B:B,Cálculo_Categorías!$F$4)) -> 4033.85 | G18: {=+_xlfn.IFS(Tabla9[[#This Row],[FACTURACIÓN]]<200,"Sin Categoría",Tabla9[[#This Row],[FACTURACIÓN]]<500,"A",Tabla9[[#This Row],[FACTURACIÓN]]<1000,"AA",Tabla9[[#This Row],[FACTURACIÓN]]>=1000,"AAA")} -> AAA
